test_0 (__main__.lab2a)
[Lab 2] - [Investigation 1] - [Part 1] - variables & printing - Test for file creation: ./lab2a.py ... ok
test_1 (__main__.lab2a)
[Lab 2] - [Investigation 1] - [Part 1] - variables & printing - Test for errors running: ./lab2a.py ... /usr/lib/python3.10/subprocess.py:767: ResourceWarning: unclosed file <_io.TextIOWrapper name=3 encoding='UTF-8'>
  _cleanup()
ResourceWarning: Enable tracemalloc to get the object allocation traceback
FAIL

======================================================================
FAIL: test_1 (__main__.lab2a)
[Lab 2] - [Investigation 1] - [Part 1] - variables & printing - Test for errors running: ./lab2a.py
----------------------------------------------------------------------
Traceback (most recent call last):
  File "/home/azahid19/ops445/lab2/./CheckLab2.py", line 55, in test_1
    self.assertEqual(return_code, 0, msg=error_output)
AssertionError: 1 != 0 : your program exited with an error (HINT: try running your program to see the error)

----------------------------------------------------------------------
Ran 2 tests in 0.321s

FAILED (failures=1)
OPS445 Lab Report - System Information for running ./CheckLab2.py
=================================================================
    User login name: azahid19
    Git Email: azahid19@myseneca.ca
    Linux system name: azahid19-OPS445
    Python executable: /usr/bin/python3
    Python version:  3.10.12 (main, Nov 20 2023, 15:14:05) [GCC 11.4.0]
    OS Platform: linux
    Working Directory: /home/azahid19/ops445/lab2
    Start at: Thu May 23 15:05:53 2024
=================================================================
